<?xml version="1.0" ?>
<robot name="Sim_robot" xmlns:xacro="http://www.ros.org/wiki/xacro">

<xacro:include filename="$(find Sim_robot_description)/urdf/materials.xacro" />
<xacro:include filename="$(find Sim_robot_description)/urdf/Sim_robot.trans" />
<xacro:include filename="$(find Sim_robot_description)/urdf/Sim_robot.gazebo" />
<link name="base_link">
  <inertial>
    <origin xyz="0.0029860466301523513 0.0 0.0520105516681608" rpy="0 0 0"/>
    <mass value="2.269996702323757"/>
    <inertia ixx="0.007773" iyy="0.008184" izz="0.014652" ixy="0.0" iyz="0.0" ixz="-0.000241"/>
  </inertial>
  <visual>
    <origin xyz="0 0 0" rpy="0 0 0"/>
    <geometry>
      <mesh filename="package://Sim_robot_description/meshes/base_link.stl" scale="0.001 0.001 0.001"/>
    </geometry>
    <material name="silver"/>
  </visual>
  <collision>
    <origin xyz="0 0 0" rpy="0 0 0"/>
    <geometry>
      <mesh filename="package://Sim_robot_description/meshes/base_link.stl" scale="0.001 0.001 0.001"/>
    </geometry>
  </collision>
</link>

<link name="left_wheel_1">
  <inertial>
    <origin xyz="-5.790023100122029e-18 -0.012499999999999997 0.0" rpy="0 0 0"/>
    <mass value="0.1826050729899067"/>
    <inertia ixx="0.000124" iyy="0.000228" izz="0.000124" ixy="-0.0" iyz="0.0" ixz="0.0"/>
  </inertial>
  <visual>
    <origin xyz="-0.0 0.1 -0.05" rpy="0 0 0"/>
    <geometry>
      <mesh filename="package://Sim_robot_description/meshes/left_wheel_1.stl" scale="0.001 0.001 0.001"/>
    </geometry>
    <material name="silver"/>
  </visual>
  <collision>
    <origin xyz="-0.0 0.1 -0.05" rpy="0 0 0"/>
    <geometry>
      <mesh filename="package://Sim_robot_description/meshes/left_wheel_1.stl" scale="0.001 0.001 0.001"/>
    </geometry>
  </collision>
</link>

<link name="right_wheel_1">
  <inertial>
    <origin xyz="-5.790023100122029e-18 0.012499999999999997 0.0" rpy="0 0 0"/>
    <mass value="0.1826050729899067"/>
    <inertia ixx="0.000124" iyy="0.000228" izz="0.000124" ixy="0.0" iyz="-0.0" ixz="0.0"/>
  </inertial>
  <visual>
    <origin xyz="-0.0 -0.1 -0.05" rpy="0 0 0"/>
    <geometry>
      <mesh filename="package://Sim_robot_description/meshes/right_wheel_1.stl" scale="0.001 0.001 0.001"/>
    </geometry>
    <material name="silver"/>
  </visual>
  <collision>
    <origin xyz="-0.0 -0.1 -0.05" rpy="0 0 0"/>
    <geometry>
      <mesh filename="package://Sim_robot_description/meshes/right_wheel_1.stl" scale="0.001 0.001 0.001"/>
    </geometry>
  </collision>
</link>

<link name="lidar_sensor_1">
  <inertial>
    <origin xyz="0.0 -4.448346221359805e-18 0.010000000000000009" rpy="0 0 0"/>
    <mass value="0.5015581250338678"/>
    <inertia ixx="0.000144" iyy="0.000144" izz="0.000255" ixy="-0.0" iyz="-0.0" ixz="0.0"/>
  </inertial>
  <visual>
    <origin xyz="-0.05 -0.0 -0.105" rpy="0 0 0"/>
    <geometry>
      <mesh filename="package://Sim_robot_description/meshes/lidar_sensor_1.stl" scale="0.001 0.001 0.001"/>
    </geometry>
    <material name="silver"/>
  </visual>
  <collision>
    <origin xyz="-0.05 -0.0 -0.105" rpy="0 0 0"/>
    <geometry>
      <mesh filename="package://Sim_robot_description/meshes/lidar_sensor_1.stl" scale="0.001 0.001 0.001"/>
    </geometry>
  </collision>
</link>

<joint name="Revolute 1" type="continuous">
  <origin xyz="0.0 -0.1 0.05" rpy="0 0 0"/>
  <parent link="base_link"/>
  <child link="left_wheel_1"/>
  <axis xyz="0.0 -1.0 0.0"/>
</joint>

<joint name="Revolute 2" type="continuous">
  <origin xyz="0.0 0.1 0.05" rpy="0 0 0"/>
  <parent link="base_link"/>
  <child link="right_wheel_1"/>
  <axis xyz="0.0 1.0 0.0"/>
</joint>

<joint name="Rigid 3" type="fixed">
  <origin xyz="0.05 0.0 0.105" rpy="0 0 0"/>
  <parent link="base_link"/>
  <child link="lidar_sensor_1"/>
</joint>

</robot>
